<?xml version='1.0'?>
<sdf version='1.6'>
  <model name='car1'>
      <!-- <static>true</static> -->
    <include>
      <uri>model://chassis1</uri>
      <pose>0 0 0 0 0 0</pose>
    </include>
    <!-- including a left rear wheel -->
    <include>
      <uri>model://wheel_left1</uri>
      <pose>-0.152 0.081 0 0 0 0</pose>
      <name>wheel_rear_left1</name>
    </include>
    <!-- including a front rear wheel -->
    <include>
      <uri>model://wheel_right1</uri>
      <pose>-0.152 -0.081 0 0 0 0</pose>
      <name>wheel_rear_right1</name>
    </include>
    <!-- including a left steering comp. -->
    <include>
      <uri>model://steering_column1</uri>
      <pose>0.112 0.0725 0 0 0 0</pose>
      <name>steer_left1</name>
    </include>
    <!-- including a right steering comp. -->
    <include>
      <uri>model://steering_column1</uri>
      <pose>0.112 -0.0725 0 0 0 0</pose>
      <name>steer_right1</name>
    </include>
    <!-- including a left front wheel -->
    <include>
      <uri>model://wheel_left1</uri>
      <pose>0.118 0.081 0 0 0 0</pose>
      <name>wheel_front_left1</name>
    </include>
    <!-- including a right front wheel -->
    <include>
      <uri>model://wheel_right1</uri>
      <pose>0.118 -0.081 0 0 0 0</pose>
      <name>wheel_front_right1</name>
    </include>
    
    <!-- including the camera link -->
    <!-- 0.261799388 -->

    <!-- realsense -->
    <include>
      <uri>model://camera</uri>
      <!-- <pose>0.1 0 0.16 0 0.15 -0.0</pose> -->
      <pose>0 0.05 0.2 0 0.2617 -0.</pose>
      <name>camera1</name>
    </include>

    <!-- includeing the car body -->
    <include>
      <uri>model://car_body1</uri>
      <pose>-0.024 0.0 -0.028 0 0.0 0</pose>
      <name>car_body1</name>
    </include>

    <!-- LIST OF JOINTS -->
    <joint name='joint_leftrear_rim1' type='revolute'>
      <parent>chassis1::link</parent>
      <child>wheel_rear_left1::link_rim</child>
      <pose frame=''>0 0 0 0 -0 0</pose>
      <axis>
        <xyz>0 0 -1</xyz>
        <use_parent_model_frame>0</use_parent_model_frame>
        <limit>
          <lower>-1.79769e+308</lower>
          <upper>1.79769e+308</upper>
          <effort>-1</effort>
          <velocity>-1</velocity>
        </limit>
        <dynamics>
          <spring_reference>0</spring_reference>
          <spring_stiffness>0</spring_stiffness>
          <damping>0</damping>
          <friction>0</friction>
        </dynamics>
      </axis>
      <physics>
        <ode>
          <limit>
            <cfm>0</cfm>
            <erp>0.2</erp>
          </limit>
          <suspension>
            <cfm>0</cfm>
            <erp>0.2</erp>
          </suspension>
        </ode>
      </physics>
    </joint>

    <joint name='joint_rightrear_rim1' type='revolute'>
      <parent>chassis1::link</parent>
      <child>wheel_rear_right1::link_rim</child>
      <pose frame=''>0 0 0 0 -0 0</pose>
      <axis>
        <xyz>0 0 -1</xyz>
        <use_parent_model_frame>0</use_parent_model_frame>
        <limit>
          <lower>-1.79769e+308</lower>
          <upper>1.79769e+308</upper>
          <effort>-1</effort>
          <velocity>-1</velocity>
        </limit>
        <dynamics>
          <spring_reference>0</spring_reference>
          <spring_stiffness>0</spring_stiffness>
          <damping>0</damping>
          <friction>0</friction>
        </dynamics>
      </axis>
      <physics>
        <ode>
          <limit>
            <cfm>0</cfm>
            <erp>0.2</erp>
          </limit>
          <suspension>
            <cfm>0</cfm>
            <erp>0.2</erp>
          </suspension>
        </ode>
      </physics>
    </joint>
    
    <!-- Front right joint between the chassis1 and the steering comp. -->
    <joint name='joint_leftfront_steer1' type='revolute'>
      <parent>chassis1::link</parent>
      <child>steer_left1::link_steer</child>
      <pose frame=''>0 0 0.005 0 -0 0</pose>
      <axis>
        <xyz>0 1 0</xyz>
        <use_parent_model_frame>0</use_parent_model_frame>
        <limit>
          <lower>-1.79769e+308</lower>
          <upper>1.79769e+308</upper>
          <effort>-1</effort>
          <velocity>-1</velocity>
        </limit>
        <dynamics>
          <spring_reference>0</spring_reference>
          <spring_stiffness>0</spring_stiffness>
          <damping>0</damping>
          <friction>0</friction>
        </dynamics>
      </axis>
      <physics>
        <ode>
          <limit>
            <cfm>0</cfm>
            <erp>0.2</erp>
          </limit>
          <suspension>
            <cfm>0</cfm>
            <erp>0.2</erp>
          </suspension>
        </ode>
      </physics>
    </joint>
    <!-- Front left joint between the chassis1 and the steering comp. -->
    <joint name='joint_rightfront_steer1' type='revolute'>
      <parent>chassis1::link</parent>
      <child>steer_right1::link_steer</child>
      <pose frame=''>0 0 -0.005 0 -0 0</pose>
      <axis>
        <xyz>0 1 0</xyz>
        <use_parent_model_frame>0</use_parent_model_frame>
        <limit>
          <lower>-1.79769e+308</lower>
          <upper>1.79769e+308</upper>
          <effort>-1</effort>
          <velocity>-1</velocity>
        </limit>
        <dynamics>
          <spring_reference>0</spring_reference>
          <spring_stiffness>0</spring_stiffness>
          <damping>0</damping>
          <friction>0</friction>
        </dynamics>
      </axis>
      <physics>
        <ode>
          <limit>
            <cfm>0</cfm>
            <erp>0.2</erp>
          </limit>
          <suspension>
            <cfm>0</cfm>
            <erp>0.2</erp>
          </suspension>
        </ode>
      </physics>
    </joint>

    <!-- Right joint between the steering and the rim   -->
    <joint name='joint_rightfront_rim1' type='revolute'>
      <parent>steer_right1::link_steer</parent>
      <child>wheel_front_right1::link_rim</child>
      <pose frame=''>0 0 0 0 -0 0</pose>
      <axis>
        <xyz>0 0 -1</xyz>
        <use_parent_model_frame>0</use_parent_model_frame>
        <limit>
          <lower>-1.79769e+308</lower>
          <upper>1.79769e+308</upper>
          <effort>-1</effort>
          <velocity>-1</velocity>
        </limit>
        <dynamics>
          <spring_reference>0</spring_reference>
          <spring_stiffness>0</spring_stiffness>
          <damping>0</damping>
          <friction>0</friction>
        </dynamics>
      </axis>
      <physics>
        <ode>
          <limit>
            <cfm>0</cfm>
            <erp>0.2</erp>
          </limit>
          <suspension>
            <cfm>0</cfm>
            <erp>0.2</erp>
          </suspension>
        </ode>
      </physics>
    </joint>

    <!-- Left joint between the steering and the rim   -->
    <joint name='joint_leftfront_rim1' type='revolute'>
      <parent>steer_left1::link_steer</parent>
      <child>wheel_front_left1::link_rim</child>
      <pose frame=''>0 0 0 0 -0 0</pose>
      <axis>
        <xyz>0 0 -1</xyz>
        <use_parent_model_frame>0</use_parent_model_frame>
        <limit>
          <lower>-1.79769e+308</lower>
          <upper>1.79769e+308</upper>
          <effort>-1</effort>
          <velocity>-1</velocity>
        </limit>
        <dynamics>
          <spring_reference>0</spring_reference>
          <spring_stiffness>0</spring_stiffness>
          <damping>0</damping>
          <friction>0</friction>
        </dynamics>
      </axis>
      <physics>
        <ode>
          <limit>
            <cfm>0</cfm>
            <erp>0.2</erp>
          </limit>
          <suspension>
            <cfm>0</cfm>
            <erp>0.2</erp>
          </suspension>
        </ode>
      </physics>
    </joint>

    <!-- fixed joint for the car body -->
    <joint name='joint_body1' type='fixed'>
      <parent>chassis1::link</parent>
      <child>car_body1::link</child>
      <pose frame=''>0 0 0 0 -0 0</pose>
      <physics>
        <ode>
          <limit>
            <cfm>0</cfm>
            <erp>0.2</erp>
          </limit>
          <suspension>
            <cfm>0</cfm>
            <erp>0.2</erp>
          </suspension>
        </ode>
      </physics>
    </joint>


    <!-- fixed joint for the camera -->
    <joint name='joint_camera1' type='fixed'>
      <parent>chassis1::link</parent>
      <child>camera1::link_camera</child>
      <pose frame=''>0 0 0 0 -0 0</pose>
      <physics>
        <ode>
          <limit>
            <cfm>0</cfm>
            <erp>0.2</erp>
          </limit>
          <suspension>
            <cfm>0</cfm>
            <erp>0.2</erp>
          </suspension>
        </ode>
      </physics>
    </joint>

    <!-- Plugin  -->
    <plugin name='CarLikeRobotPlugin' filename='libcar_plugin.so'>
      <robotNamespace>car1</robotNamespace>
      <wheelbase>0.26</wheelbase>
      <axletrack>0.162</axletrack>
      <wheelradius>0.0325</wheelradius>
      <speed_wheel_joints> 
        <front_wheel_joints>
          <leftjoint>joint_leftfront_rim1</leftjoint>
          <rightjoint>joint_rightfront_rim1</rightjoint>
        </front_wheel_joints>
        <rear_wheel_joints>
          <leftjoint>joint_leftrear_rim1</leftjoint>
          <rightjoint>joint_rightrear_rim1</rightjoint>
        </rear_wheel_joints>
        <kp>0.01</kp>
        <ki>0.0</ki>
        <kd>0.0</kd>
      </speed_wheel_joints>
      <steer_wheel_joints>
        <leftjoint>joint_leftfront_steer1</leftjoint>
        <rightjoint>joint_rightfront_steer1</rightjoint>
        <kp>10</kp>
        <ki>0.0</ki>
        <kd>0.1</kd>
      </steer_wheel_joints>
      <initial_steer>0.0</initial_steer>
      <initial_speed>0.0</initial_speed>
    </plugin>

    <plugin name='bno055' filename='libbno055_plugin.so'> 
      <rosTopicNamespace>car1</rosTopicNamespace>
    </plugin>
    <plugin name='gps' filename='libgps_plugin.so'> 
      <rosTopicNamespace>car1</rosTopicNamespace>
    </plugin>
    
  </model>
</sdf>
